Workbook

Sheet 履歴書
B2: 履 歴 書
N3: =TODAY() | Q3: 現在
B5: フリガナ | E5: フィルザ チャンドラ サンジャ やぷとら | T5: 顔写真
B6: 名前 | E6: Firza Chandra Sandjaya Putra
B8: 生年月日 | E8: 36153 | K8: 満 | L8: =IF(NOT(OR(ISBLANK(E8),ISERROR(VALUE(E8)))),DATEDIF(E8,$N$3,"Y"),"") | M8: 歳 | N8: 性別 | O8: 男性
B10: フリガナ | E10: 〒 | F10: ジャカルタ | H10: インドネシア
B11: 現住所 | E11: Jakarta, Indonesia
B13: 電話番号 | E13: =628515983459 | M13: パスポート | P13: 有
B15: メールアドレス | E15: firzasandjaya@gmail.com | M15: 在留資格 | P15: 無
B17: 国籍 | E17: インドネシア | M17: 在留期限 | P17: 無
B19: 母語 | E19: Indonesian | M19: 日本語レベル | P19: N3合格
B22: 入学年月 | E22: 卒業年月 | H22: 学校名 | P22: 学部・専攻 | U22: 在学状況
B24: 42948 | E24: 44470 | H24: バンドン工科大学 (Bandung Institute of Technology) | P24: 産業工学 | U24: 卒業
B37: 入社年月 | E37: 退職年月 | H37: 会社名 | P37: 職種 | U37: 雇用形態
B39: 45717 | E39: 46140 | H39: PT Hypefast Karya Nusantara | P39: データエンジニア | U39: 正社員
B41: 44743 | E41: 45717 | H41: PT IDstar Cipta Teknologi (PT XL Axiata Tbk. 派遣/常駐) | P41: データエンジニア | U41: 正社員
B43: 44228 | E43: 44409 | H43: PT Telkom Indonesia | P43: データサイエンティスト | U43: インターンシップ
B53: 取得年月 | E53: 資格 | M53: 取得年月 | P53: 資格
B55: 45658 | E55: JLPT N3
B57: 45689 | E57: Data Descriptors, Statistical Distributions, and Application to Business Decisions
B68: 自己PR
B70: 私は約4年の経験を持つデータエンジニア兼AI/MLエンジニアとして、エンドツーエンドのデータパイプライン構築とスケーラブルなMLOpsフレームワークの設計を専門としています 。特に、特に、データインフラをインテリジェントな自動化へと進化させることや、ワークフローを加速させるMLモデルの展開に注力しています。 。これまで通信業界（Telco）や消費者ブランドにおいて、データ主導の自動化された意思決定を推進する、インパクトの大きいシステムを提供してきた実績があります 。
B78: 希望条件
B80: 雇用形態 | E80: 正社員
B81: 給料 | E81: 年収 600万円 〜 800万円
B82: 勤務地 | E82: 貴社の規定に従います（希望勤務地：東京近郊）
B83: 職種 | E83: データエンジニア / ML Ops / AI エンジニア
B84: 業務内容 | E84: データパイプライン構築、AI/MLモデルの実装・運用
B85: その他 | E85: 日本での就労ビザのスポンサーシップを希望いたします。現在はインドネシアに在住しておりますが、採用が決定次第、日本への入国・転居が可能です。面接はオンライン（Zoom/Google Meet等）での実施を希望いたします。

Sheet 職務経歴書（IT）
J2: 職務経歴書
R3: =TODAY() | U3: 現在
P5: 名前 | R5: ='履歴書'!E6
B7: ■スキルシート | M7: ◎：3年以上 | P7: 〇：1年以上 | S7: △：勉強したことがある
B9: OS | D9: Windows | G9: ◎ | H9: Linux | K9: ◎
D10: macOS | G10: △ | H10: Unix | K10: ◎
B12: 言語 | D12: Java | G12: △ | H12: VBA | K12: △
D13: PHP | G13: △ | H13: SQL | K13: ◎
D14: CSS | G14: △ | H14: Bash/Shell Script | K14: ◎
D15: HTML | G15: △ | H15: Java Script | K15: △
D16: Python | G16: ◎
B18: FW | D18: Flask | G18: ◎ | H18: Apache Airflow | K18: ◎ | L18: SQLAlchemy | O18: △
D19: PySpark | G19: ◎ | H19: Kafka | K19: ◎
D20: pandas | G20: ◎ | H20: TensorFlow/Keras | K20: 〇
D21: numpy | G21: ◎ | H21: PyTorch | K21: 〇
D22: FastAPI | G22: 〇 | H22: scikit-learn | K22: 〇
D23: SQLAlchemy | G23: 〇 | H23: LangChain | K23: △
B24: DB | D24: MySQL | G24: 〇 | H24: SQL Server | K24: 〇 | L24: Oracle | O24: 〇 | P24: Snowflake | S24: 〇
D25: PostgreSQL | G25: ◎ | H25: BigQuery | K25: ◎ | L25: SnowMongoDB Atlas | O25: 〇 | P25: Hive/Impala | S25: ◎
B26: 他 | D26: Docker | G26: ◎ | H26: Confluence | K26: ◎ | L26: Power BI | O26: ◎ | P26: Git | S26: ◎ | T26: Hadoop | W26: 〇
D27: Apache | G27: ◎ | H27: Metabase | K27: ◎ | L27: GCP | O27: ◎ | P27: BitBucket CI/CD | S27: ◎ | T27: Cloudera（CDH | W27: 〇
D28: Jira | G28: ◎ | H28: Tableau | K28: ◎ | L28: AWS | O28: 〇 | P28: Apache Kafka | S28: 〇 | T28: Google Apps Script | W28: △
B30: ■経験 | S30: ■作業経験
B32: 得意分野 | D32: ： | E32: データエンジニアリングおよびAI/MLシステムの構築（ETLパイプライン設計、MLOpsデプロイ、GCP・AWSでのクラウド基盤構築） | S32: 要件定義 | V32: ◎
S33: 基本設計 | V33: ◎
S34: 機能設計 | V34: ◎
S35: 詳細設計 | V35: ◎
B36: 得意技術 | D36: ： | E36: Python、SQL、PySpark、TensorFlow/Keras、FastAPI、GCP（BigQuery・Vertex AI・Cloud Run）、AWS（S3・EC2・Lambda）、Apache Airflow、Docker、Kubernetes | S36: コーディング | V36: ◎
S37: 単体テスト | V37: ◎
S38: 結合テスト | V38: ◎
S39: 総合テスト | V39: 〇
B40: その他 | D40: ： | E40: BI・データ可視化（Metabase・Looker Studio・Tableau）、データクレンジング、API統合（REST API）、プロジェクト管理（Jira・Confluence）、ブロックチェーン基礎知識 | S40: 受入テスト | V40: 〇
S41: 保守 | V41: 〇
S42: 教育 | V42: 〇
B45: ■職務経歴
B47: 会社名 | D47: ='履歴書'!H39 | M47: 雇用形態 | O47: ='履歴書'!U39
B48: 入社年月 | D48: =IF(NOT(OR(ISBLANK('履歴書'!B39),ISERROR(VALUE('履歴書'!B39)))),'履歴書'!B39,"") | I48: 退職年月 | K48: =IF(NOT(OR(ISBLANK('履歴書'!E39),ISERROR(VALUE('履歴書'!E39)))),'履歴書'!E39,"") | P48: 在籍年月 | R48: =DATEDIF(D48,K48,"Y")&"年"&DATEDIF(D48,K48,"YM")&"ヶ月"
B49: No. | C49: 期間 | E49: 業務内容 | R49: 言語・ フレームワーク | U49: OS・DB・ツール
B51: 1 | C51: 45717 | E51: 【プロジェクト名】商品レコメンデーションシステム開発 | R51: 言語： Python FW： TensorFlow/Keras scikit-learn FastAPI | U51: OS： Linux DB： BigQuery ツール： GCP: Vertex AI, Artifact Registry, Cloud Run, Composer Docker, Airflow, Metabase
E52: 【プロジェクト概要】 ShopeeマーケットプレイスにおけるNCF・補充・ベビー服向けの商品レコメンデーションシステムを構築。GCP（Vertex AI）上でエンドツーエンドのMLパイプラインを実装し、月間約3億IDRのGMV創出に貢献。 【担当業務】 ・協力会社の設計書をベースにMLモデルの開発・実装を実施 ・NCF・補充・ベビー服の3種類のレコメンドエンジンを構築 ・FastAPIを用いたエンドポイント構築とGCP Vertex AIへのデプロイ ・モデルの精度評価とチューニングを実施"
...

Sheet list
A1: 在留資格 | B1: 在学状況 | C1: 雇用形態 | D1: パスポート
A2: 無 | B2: 卒業 | C2: 正社員 | D2: 有
A3: 技術・人文知識・国際業務 | B3: 卒業見込み | C3: 契約社員 | D3: 無
A4: 企業内転勤 | B4: 退学 | C4: インターンシップ
A5: 留学 | B5: 休学 | C5: アルバイト
A6: 研修 | B6: その他 | C6: その他
A7: 家族滞在
A8: 永住者
A9: 日本人の配偶者等
A10: 永住者の配偶者等
A11: 定住者
